# 🐛 Bug Fix: ReferenceError aiPlayer is not defined

## ❌ **Error Encountered**
```
file:///C:/Users/angel/OneDrive/Desktop/spectacles-flutes/server/server.js:491
    const aiName = aiPlayer.name || "AI-1";
                   ^

ReferenceError: aiPlayer is not defined
```

## 🔍 **Root Cause**
In the `generateAIMessage()` function's catch block, the code was trying to access `aiPlayer.name` but `aiPlayer` was declared inside the try block and wasn't accessible in the catch block scope.

**Problematic Code**:
```javascript
try {
  const aiPlayer = game.players.find(p => p.id === aiPlayerId);
  // ... rest of function
} catch (error) {
  // aiPlayer is not accessible here!
  const aiName = aiPlayer.name || "AI-1"; // ❌ ReferenceError
}
```

## ✅ **Solution Applied**
Modified the catch block to safely retrieve the AI player name with proper error handling:

```javascript
} catch (error) {
  console.error(`❌ Error generating AI message for ${aiPlayerId}:`, error.message);
  
  // Try to get AI name from game data, fallback to AI-1
  let aiName = "AI-1";
  try {
    const game = games.get(gameId);
    const aiPlayerData = game?.players.find(p => p.id === aiPlayerId);
    aiName = aiPlayerData?.name || "AI-1";
  } catch (e) {
    // If we can't get the AI name, just use AI-1
    aiName = "AI-1";
  }
  
  const personalityMessages = strategicFallbacks[type][aiName] || strategicFallbacks[type]["AI-1"];
  return personalityMessages[Math.floor(Math.random() * personalityMessages.length)];
}
```

## 🎯 **What the Fix Does**

1. **Safe Variable Access**: Creates a new scope to safely access game data
2. **Graceful Fallback**: If anything fails, defaults to "AI-1" 
3. **Nested Error Handling**: Protects against multiple potential failure points
4. **Maintains Functionality**: Still provides personality-appropriate fallback messages

## ✅ **Testing Results**

- ✅ Server starts without errors
- ✅ Game creation works properly
- ✅ AI message generation functions correctly
- ✅ Error handling is robust

## 🚀 **Status**

**FIXED** - The server now runs without errors and all functionality works as expected.